<?xml version="1.0"?>
<robot name="mbot">

    <!-- 地面实体描述 -->
    <link name="floor_link">
        <visual>
            <origin xyz="0 0 0" rpy="0 0 0" />
            <geometry>
                <!-- 圆柱体高度尽量小，已达到可忽略的精度 -->
                <cylinder length="0.000001" radius="0.20" />
            </geometry>
            <material name="floor">
                <color rgba="1 0.4 0 0" />
            </material>
        </visual>
    </link>

    <!-- 底盘与地面的关节关系描述 -->
    <joint name="base_joint" type="continuous">
        <origin xyz="0 0 0.11" rpy="0 0 0" />
        <parent link="floor_link" />
        <child link="base_link" />
        <axis xyz="0 1 0" />
    </joint>

    <!-- 底盘实体描述 -->
    <link name="base_link">
        <visual>
            <origin xyz="0 0 0" rpy="0 0 0" />
            <geometry>
                <cylinder length="0.16" radius="0.20" />
            </geometry>
            <material name="yellow">
                <color rgba="1 0.4 0 1" />
            </material>
        </visual>
    </link>

    <!-- 左轮与底盘的关节描述 -->
    <joint name="left_wheel_joint" type="continuous">
        <origin xyz="0 0.19 -0.05" rpy="0 0 0" />
        <parent link="base_link" />
        <child link="left_wheel_link" />
        <axis xyz="0 1 0" />
    </joint>

    <!-- 左轮实体描述 -->
    <link name="left_wheel_link">
        <visual>
            <origin xyz="0 0 0" rpy="1.5707 0 0" />
            <geometry>
                <cylinder radius="0.06" length="0.025" />
            </geometry>
            <material name="white">
                <color rgba="1 1 1 0.9" />
            </material>
        </visual>
    </link>

    <!-- 右轮与底盘的关节描述 -->
    <joint name="right_wheel_joint" type="continuous">
        <origin xyz="0 -0.19 -0.05" rpy="0 0 0" />
        <parent link="base_link" />
        <child link="right_wheel_link" />
        <axis xyz="0 1 0" />
    </joint>

    <!-- 右轮实体描述 -->
    <link name="right_wheel_link">
        <visual>
            <origin xyz="0 0 0" rpy="1.5707 0 0" />
            <geometry>
                <cylinder radius="0.06" length="0.025" />
            </geometry>
            <material name="white">
                <color rgba="1 1 1 0.9" />
            </material>
        </visual>
    </link>

    <!-- 前脚轮实体描述 -->
    <joint name="front_caster_joint" type="continuous">
        <origin xyz="0.18 0 -0.095" rpy="0 0 0" />
        <parent link="base_link" />
        <child link="front_caster_link" />
        <axis xyz="0 1 0" />
    </joint>

    <!-- 前脚轮和底盘的关节描述 -->
    <link name="front_caster_link">
        <visual>
            <origin xyz="0 0 0" rpy="0 0 0" />
            <geometry>
                <sphere radius="0.015" />
            </geometry>
            <material name="black">
                <color rgba="0 0 0 0.95" />
            </material>
        </visual>
    </link>

    <!-- 后脚轮实体描述 -->
    <joint name="back_caster_joint" type="continuous">
        <origin xyz="-0.18 0 -0.095" rpy="0 0 0" />
        <parent link="base_link" />
        <child link="back_caster_link" />
        <axis xyz="0 1 0" />
    </joint>

    <!-- 后脚轮和底盘的关节描述 -->
    <link name="back_caster_link">
        <visual>
            <origin xyz="0 0 0" rpy="0 0 0" />
            <geometry>
                <sphere radius="0.015" />
            </geometry>
            <material name="black">
                <color rgba="0 0 0 0.95" />
            </material>
        </visual>
    </link>

    <!-- 激光雷达实体描述 -->
    <link name="laser_link">
        <visual>
            <origin xyz="0 0 0 " rpy="0 0 0" />
            <geometry>
                <cylinder length="0.05" radius="0.05" />
            </geometry>
            <material name="gray">
                <color rgba="0.25 0.25 0.25 0.95" />
            </material>
        </visual>
    </link>

    <!-- 激光雷达和底盘的关节描述 -->
    <joint name="laser_joint" type="fixed">
        <origin xyz="0 0 0.105" rpy="0 0 0" />
        <parent link="base_link" />
        <child link="laser_link" />
    </joint>

    <!-- 相机实体描述 -->
    <link name="camera_link">
        <visual>
            <origin xyz="0 0 0 " rpy="0 1.57 0" />
            <geometry>
                <cylinder radius="0.02" length = "0.05"/>
            </geometry>
            <material name="gray">
                <color rgba="0.25 0.25 0.25 0.95"/>
            </material>
        </visual>
    </link>

    <!-- 相机和底盘的关节描述 -->
    <joint name="camera_joint" type="fixed">
        <origin xyz="0.18 0 0.055" rpy="0 0 0"/>
        <parent link="base_link"/>
        <child link="camera_link"/>
    </joint>

</robot>